[   INFO] [2018-03-29 18:22:28,653] [1048] [HTMLReport.py(98)] - 预计并发线程数：5
[   INFO] [2018-03-29 18:22:28,654] [10280] [Result.py(42)] - 开始测试：test_error (__main__.test_1th)
[  ERROR] [2018-03-29 18:22:28,654] [10280] [HTMLReport_test.py(35)] - 测试错误
[   INFO] [2018-03-29 18:22:28,654] [18744] [Result.py(42)] - 开始测试：test_fail (__main__.test_1th)
[   INFO] [2018-03-29 18:22:28,655] [2836] [Result.py(42)] - 开始测试：test_isupper (__main__.test_1th)
[   INFO] [2018-03-29 18:22:28,655] [18744] [HTMLReport_test.py(45)] - 测试失败
[   INFO] [2018-03-29 18:22:28,655] [2836] [HTMLReport_test.py(20)] - 测试isupper
[   INFO] [2018-03-29 18:22:28,656] [17268] [Result.py(42)] - 开始测试：test_skip (__main__.test_1th)
[   INFO] [2018-03-29 18:22:28,656] [2836] [HTMLReport_test.py(21)] - 11111111111111111111111111111111111111111111111111111
[   INFO] [2018-03-29 18:22:28,656] [5348] [Result.py(42)] - 开始测试：test_split (__main__.test_1th)
[WARNING] [2018-03-29 18:22:28,657] [18744] [Result.py(117)] - 测试未通过：	test_fail (__main__.test_1th)
Traceback (most recent call last):
  File "C:/Users/liush/Documents/GitHub/HTMLReport/tests/HTMLReport_test.py", line 46, in test_fail
    self.assertEqual(1, 2, "相等")
AssertionError: 1 != 2 : 相等

[   INFO] [2018-03-29 18:22:28,658] [17268] [Result.py(70)] - 跳过测试：	test_skip (__main__.test_1th)
这是一个跳过的测试
[   INFO] [2018-03-29 18:22:28,658] [2836] [Result.py(85)] - 测试执行通过：test_isupper (__main__.test_1th)
[   INFO] [2018-03-29 18:22:28,659] [5348] [HTMLReport_test.py(27)] - 测试split
[   INFO] [2018-03-29 18:22:28,659] [18744] [Result.py(51)] - 测试结束：test_fail (__main__.test_1th)
[   INFO] [2018-03-29 18:22:28,659] [17268] [Result.py(51)] - 测试结束：test_skip (__main__.test_1th)
[   INFO] [2018-03-29 18:22:28,659] [2836] [Result.py(51)] - 测试结束：test_isupper (__main__.test_1th)
[   INFO] [2018-03-29 18:22:28,660] [5348] [Result.py(85)] - 测试执行通过：test_split (__main__.test_1th)
[   INFO] [2018-03-29 18:22:28,660] [5348] [Result.py(51)] - 测试结束：test_split (__main__.test_1th)
[  ERROR] [2018-03-29 18:22:28,667] [10280] [Result.py(101)] - 测试产生错误：	test_error (__main__.test_1th)
Traceback (most recent call last):
  File "C:/Users/liush/Documents/GitHub/HTMLReport/tests/HTMLReport_test.py", line 41, in test_error
    raise ValueError
ValueError

[   INFO] [2018-03-29 18:22:28,668] [10280] [Result.py(51)] - 测试结束：test_error (__main__.test_1th)
[   INFO] [2018-03-29 18:22:28,668] [19592] [Result.py(42)] - 开始测试：test_bad_int (__main__.test_2th)
[   INFO] [2018-03-29 18:22:28,668] [19592] [HTMLReport_test.py(58)] - 测试异常类型
[   INFO] [2018-03-29 18:22:28,669] [15544] [Result.py(42)] - 开始测试：test_upper (__main__.test_2th)
[  ERROR] [2018-03-29 18:22:28,669] [19592] [Result.py(101)] - 测试产生错误：	test_bad_int (__main__.test_2th)
Traceback (most recent call last):
  File "C:/Users/liush/Documents/GitHub/HTMLReport/tests/HTMLReport_test.py", line 59, in test_bad_int
    self.assertRaises(ValueError, parse_int("1.5"), 'N/A')
  File "C:/Users/liush/Documents/GitHub/HTMLReport/tests/HTMLReport_test.py", line 11, in parse_int
    return int(s)
ValueError: invalid literal for int() with base 10: '1.5'

[   INFO] [2018-03-29 18:22:28,670] [19592] [Result.py(51)] - 测试结束：test_bad_int (__main__.test_2th)
[CRITICAL] [2018-03-29 18:22:28,669] [15544] [HTMLReport_test.py(63)] - 测试相等
[WARNING] [2018-03-29 18:22:28,670] [15544] [Result.py(117)] - 测试未通过：	test_upper (__main__.test_2th)
Traceback (most recent call last):
  File "C:/Users/liush/Documents/GitHub/HTMLReport/tests/HTMLReport_test.py", line 64, in test_upper
    self.assertEqual('foo'.upper(), '00')
AssertionError: 'FOO' != '00'
- FOO
+ 00


[   INFO] [2018-03-29 18:22:28,670] [15544] [Result.py(51)] - 测试结束：test_upper (__main__.test_2th)
[   INFO] [2018-03-29 18:22:28,671] [2116] [Result.py(42)] - 开始测试：test_False (__main__.test_第三个测试)
[   INFO] [2018-03-29 18:22:28,671] [19580] [Result.py(42)] - 开始测试：test_True (__main__.test_第三个测试)
[WARNING] [2018-03-29 18:22:28,671] [2116] [Result.py(117)] - 测试未通过：	test_False (__main__.test_第三个测试)
Traceback (most recent call last):
  File "C:/Users/liush/Documents/GitHub/HTMLReport/tests/HTMLReport_test.py", line 83, in test_False
    self.assertFalse(True, self.a)
AssertionError: True is not false : 2

[   INFO] [2018-03-29 18:22:28,672] [2116] [Result.py(51)] - 测试结束：test_False (__main__.test_第三个测试)
[WARNING] [2018-03-29 18:22:28,672] [19580] [Result.py(117)] - 测试未通过：	test_True (__main__.test_第三个测试)
Traceback (most recent call last):
  File "C:/Users/liush/Documents/GitHub/HTMLReport/tests/HTMLReport_test.py", line 78, in test_True
    self.assertTrue(False, self.a)
AssertionError: False is not true : 3

[   INFO] [2018-03-29 18:22:28,672] [19580] [Result.py(51)] - 测试结束：test_True (__main__.test_第三个测试)
[   INFO] [2018-03-29 18:22:28,672] [1048] [HTMLReport.py(125)] - 
Pass	test_isupper (__main__.test_1th)	测试isupper
Pass	test_split (__main__.test_1th)	测试split

[  ERROR] [2018-03-29 18:22:28,672] [1048] [HTMLReport.py(127)] - 
Fail	test_fail (__main__.test_1th)	测试失败
Skip	test_skip (__main__.test_1th)	测试跳过
Error	test_error (__main__.test_1th)	测试错误
Error	test_bad_int (__main__.test_2th)	测试异常类型
Fail	test_upper (__main__.test_2th)	测试相等
Fail	test_False (__main__.test_第三个测试)	测试FALSE
Fail	test_True (__main__.test_第三个测试)	测试True

[   INFO] [2018-03-29 18:22:28,692] [1048] [HTMLReport.py(138)] - 
测试结束！
运行时间: 0:00:00.018987
共计执行用例数量：9
执行成功用例数量：2
执行失败用例数量：4
跳过执行用例数量：1
产生异常用例数量：2
